<?xml version="1.0" encoding="utf-8"?>

<robot
  name="bot1">
  <link
    name="base_link">
    <inertial>
      <origin
        xyz="0.045732 0.09332 1.1107E-16"
        rpy="0 0 0" />
      <mass
        value="2.0304" />
      <inertia
        ixx="0.072006"
        ixy="-0.00042676"
        ixz="-3.7413E-17"
        iyy="0.092836"
        iyz="-5.2298E-18"
        izz="0.036075" />
    </inertial>
    <visual>
      <origin
        xyz="0 0 0"
        rpy="0 0 0" />
      <geometry>
        <mesh
          filename="package://bot1/meshes/base_link.STL" />
      </geometry>
      <material
        name="">
        <color
          rgba="0.79216 0.81961 0.93333 1" />
      </material>
    </visual>
    <collision>
      <origin
        xyz="0 0 0"
        rpy="0 0 0" />
      <geometry>
        <mesh
          filename="package://bot1/meshes/base_link.STL" />
      </geometry>
    </collision>
  </link>
  <link
    name="B">
    <inertial>
      <origin
        xyz="0.005 0.1 2.2811E-17"
        rpy="0 0 0" />
      <mass
        value="0.76" />
      <inertia
        ixx="0.011679"
        ixy="1.0729E-20"
        ixz="1.7754E-20"
        iyy="0.0091517"
        iyz="1.7658E-19"
        izz="0.0025397" />
    </inertial>
    <visual>
      <origin
        xyz="0.175 0 0"
        rpy="0 0 0" />
      <geometry>
        <mesh
          filename="package://bot1/meshes/B.STL" />
      </geometry>
      <material
        name="">
        <color
          rgba="0.79216 0.81961 0.93333 1" />
      </material>
    </visual>
    <collision>
      <origin
        xyz="0.175 0 0"
        rpy="0 0 0" />
      <geometry>
        <mesh
          filename="package://bot1/meshes/B.STL" />
      </geometry>
    </collision>
  </link>
  <joint
    name="BJ"
    type="prismatic">
    <origin
      xyz="-0.175 0 0.001"
      rpy="1.5708 0 0" />
    <parent
      link="base_link" />
    <child
      link="B" />
    <axis
      xyz="0 -1 0" />
    <limit
      lower="-0.15"
      upper="0"
      effort="100"
      velocity="0.1" />
    <safety_controller
      k_velocity="0" />
  </joint>
  <link
    name="FRW">
    <inertial>
      <origin
        xyz="-2.7756E-17 -3.7636E-05 -0.048156"
        rpy="0 0 0" />
      <mass
        value="0.16694" />
      <inertia
        ixx="0.00011342"
        ixy="0"
        ixz="2.647E-21"
        iyy="0.00011354"
        iyz="-6.1853E-08"
        izz="0.00019663" />
    </inertial>
    <visual>
      <origin
        xyz="0 0 0"
        rpy="0 0 0" />
      <geometry>
        <mesh
          filename="package://bot1/meshes/FRW.STL" />
      </geometry>
      <material
        name="">
        <color
          rgba="0.79216 0.81961 0.93333 1" />
      </material>
    </visual>
    <collision>
      <origin
        xyz="0 0 0"
        rpy="0 0 0" />
      <geometry>
        <mesh
          filename="package://bot1/meshes/FRW.STL" />
      </geometry>
    </collision>
  </link>
  <joint
    name="FRWJ"
    type="continuous">
    <origin
      xyz="0.095 -0.17 0.047"
      rpy="1.5707963267949 0.39309481042652 -3.14159265358979" />
    <parent
      link="base_link" />
    <child
      link="FRW" />
    <axis
      xyz="0 0 1" />
    <safety_controller
      k_velocity="0" />
  </joint>
  <link
    name="RRW">
    <inertial>
      <origin
        xyz="0 -3.7636E-05 -0.048156"
        rpy="0 0 0" />
      <mass
        value="0.16694" />
      <inertia
        ixx="0.00011342"
        ixy="1.0164E-20"
        ixz="2.6933E-21"
        iyy="0.00011354"
        iyz="-6.1853E-08"
        izz="0.00019663" />
    </inertial>
    <visual>
      <origin
        xyz="0 0 0"
        rpy="0 0 0" />
      <geometry>
        <mesh
          filename="package://bot1/meshes/RRW.STL" />
      </geometry>
      <material
        name="">
        <color
          rgba="0.79216 0.81961 0.93333 1" />
      </material>
    </visual>
    <collision>
      <origin
        xyz="0 0 0"
        rpy="0 0 0" />
      <geometry>
        <mesh
          filename="package://bot1/meshes/RRW.STL" />
      </geometry>
    </collision>
  </link>
  <joint
    name="RRWJ"
    type="continuous">
    <origin
      xyz="-0.065 -0.17 0.047"
      rpy="1.5707963267949 0.393094810426521 -3.14159265358979" />
    <parent
      link="base_link" />
    <child
      link="RRW" />
    <axis
      xyz="0 0 1" />
    <safety_controller
      k_velocity="0" />
  </joint>
  <link
    name="FLW">
    <inertial>
      <origin
        xyz="1.3878E-17 -3.7636E-05 -0.048156"
        rpy="0 0 0" />
      <mass
        value="0.16694" />
      <inertia
        ixx="0.00011342"
        ixy="-3.1238E-22"
        ixz="-9.8323E-22"
        iyy="0.00011354"
        iyz="-6.1853E-08"
        izz="0.00019663" />
    </inertial>
    <visual>
      <origin
        xyz="0 0 0"
        rpy="0 0 0" />
      <geometry>
        <mesh
          filename="package://bot1/meshes/FLW.STL" />
      </geometry>
      <material
        name="">
        <color
          rgba="0.79216 0.81961 0.93333 1" />
      </material>
    </visual>
    <collision>
      <origin
        xyz="0 0 0"
        rpy="0 0 0" />
      <geometry>
        <mesh
          filename="package://bot1/meshes/FLW.STL" />
      </geometry>
    </collision>
  </link>
  <joint
    name="FLWJ"
    type="continuous">
    <origin
      xyz="0.095 0.17 0.047"
      rpy="1.5707963267949 0 0" />
    <parent
      link="base_link" />
    <child
      link="FLW" />
    <axis
      xyz="0 0 -1" />
    <safety_controller
      k_velocity="0" />
  </joint>
  <link
    name="RLW">
    <inertial>
      <origin
        xyz="0 -3.7636E-05 -0.048156"
        rpy="0 0 0" />
      <mass
        value="0.16694" />
      <inertia
        ixx="0.00011342"
        ixy="-2.065E-22"
        ixz="-9.8323E-22"
        iyy="0.00011354"
        iyz="-6.1853E-08"
        izz="0.00019663" />
    </inertial>
    <visual>
      <origin
        xyz="0 0 0"
        rpy="0 0 0" />
      <geometry>
        <mesh
          filename="package://bot1/meshes/RLW.STL" />
      </geometry>
      <material
        name="">
        <color
          rgba="0.79216 0.81961 0.93333 1" />
      </material>
    </visual>
    <collision>
      <origin
        xyz="0 0 0"
        rpy="0 0 0" />
      <geometry>
        <mesh
          filename="package://bot1/meshes/RLW.STL" />
      </geometry>
    </collision>
  </link>
  <joint
    name="RLWJ"
    type="continuous">
    <origin
      xyz="-0.065 0.17 0.047"
      rpy="1.5707963267949 0 0" />
    <parent
      link="base_link" />
    <child
      link="RLW" />
    <axis
      xyz="0 0 -1" />
    <safety_controller
      k_velocity="0" />
  </joint>
  <link
    name="RC">
    <inertial>
      <origin
        xyz="0.015 0 0"
        rpy="0 0 0" />
      <mass
        value="0.075" />
      <inertia
        ixx="3.125E-05"
        ixy="-1.6263E-22"
        ixz="4.2352E-22"
        iyy="2.125E-05"
        iyz="-1.0334E-21"
        izz="2.125E-05" />
    </inertial>
    <visual>
      <origin
        xyz="0 0 0"
        rpy="0 0 0" />
      <geometry>
        <mesh
          filename="package://bot1/meshes/RC.STL" />
      </geometry>
      <material
        name="">
        <color
          rgba="0.79216 0.81961 0.93333 1" />
      </material>
    </visual>
    <collision>
      <origin
        xyz="0 0 0"
        rpy="0 0 0" />
      <geometry>
        <mesh
          filename="package://bot1/meshes/RC.STL" />
      </geometry>
    </collision>
  </link>
  <joint
    name="RCJ"
    type="fixed">
    <origin
      xyz="0.03 -0.23 0.125"
      rpy="1.5707963267949 0 1.5707963267949" />
    <parent
      link="base_link" />
    <child
      link="RC" />
    <axis
      xyz="0 0 0" />
    <safety_controller
      k_velocity="0" />
  </joint>
  <link
    name="LC">
    <inertial>
      <origin
        xyz="0.015 0 0"
        rpy="0 0 0" />
      <mass
        value="0.075" />
      <inertia
        ixx="3.125E-05"
        ixy="1.6263E-22"
        ixz="-4.2352E-22"
        iyy="2.125E-05"
        iyz="-1.0334E-21"
        izz="2.125E-05" />
    </inertial>
    <visual>
      <origin
        xyz="0 0 0"
        rpy="0 0 0" />
      <geometry>
        <mesh
          filename="package://bot1/meshes/LC.STL" />
      </geometry>
      <material
        name="">
        <color
          rgba="0.79216 0.81961 0.93333 1" />
      </material>
    </visual>
    <collision>
      <origin
        xyz="0 0 0"
        rpy="0 0 0" />
      <geometry>
        <mesh
          filename="package://bot1/meshes/LC.STL" />
      </geometry>
    </collision>
  </link>
  <joint
    name="LCJ"
    type="fixed">
    <origin
      xyz="0.03 0.23 0.125"
      rpy="-1.5707963267949 0 -1.5707963267949" />
    <parent
      link="base_link" />
    <child
      link="LC" />
    <axis
      xyz="0 0 0" />
    <safety_controller
      k_velocity="0" />
  </joint>
  <link
    name="RA">
    <inertial>
      <origin
        xyz="0.064226 0 0"
        rpy="0 0 0" />
      <mass
        value="0.11493" />
      <inertia
        ixx="1.7546E-05"
        ixy="1.3293E-21"
        ixz="-5.3917E-21"
        iyy="0.0001712"
        iyz="-2.9655E-21"
        izz="0.00017089" />
    </inertial>
    <visual>
      <origin
        xyz="0 0 0"
        rpy="0 0 0" />
      <geometry>
        <mesh
          filename="package://bot1/meshes/RA.STL" />
      </geometry>
      <material
        name="">
        <color
          rgba="0.79216 0.81961 0.93333 1" />
      </material>
    </visual>
    <collision>
      <origin
        xyz="0 0 0"
        rpy="0 0 0" />
      <geometry>
        <mesh
          filename="package://bot1/meshes/RA.STL" />
      </geometry>
    </collision>
  </link>
  <joint
    name="RAJ"
    type="fixed">
    <origin
      xyz="0.175 -0.185 0.055"
      rpy="1.5707963267949 0 0" />
    <parent
      link="base_link" />
    <child
      link="RA" />
    <axis
      xyz="0 0 0" />
    <safety_controller
      k_velocity="0" />
  </joint>
  <link
    name="RF">
    <inertial>
      <origin
        xyz="0.075327 1.3878E-17 0.0052437"
        rpy="0 0 0" />
      <mass
        value="0.24614" />
      <inertia
        ixx="0.00024699"
        ixy="1.1698E-20"
        ixz="-4.7172E-05"
        iyy="0.00069522"
        iyz="3.0415E-20"
        izz="0.00092098" />
    </inertial>
    <visual>
      <origin
        xyz="0 0 0"
        rpy="0 0 0" />
      <geometry>
        <mesh
          filename="package://bot1/meshes/RF.STL" />
      </geometry>
      <material
        name="">
        <color
          rgba="0.79216 0.81961 0.93333 1" />
      </material>
    </visual>
    <collision>
      <origin
        xyz="0 0 0"
        rpy="0 0 0" />
      <geometry>
        <mesh
          filename="package://bot1/meshes/RF.STL" />
      </geometry>
    </collision>
  </link>
  <joint
    name="RFJ"
    type="revolute">
    <origin
      xyz="0.135 0 0"
      rpy="0 0.7854 0" />
    <parent
      link="RA" />
    <child
      link="RF" />
    <axis
      xyz="0 1 0" />
    <limit
      lower="-1.309"
      upper="0.7854"
      effort="100"
      velocity="0.125" />
    <safety_controller
      k_velocity="0" />
  </joint>
  <link
    name="LA">
    <inertial>
      <origin
        xyz="0.064226 0 0"
        rpy="0 0 0" />
      <mass
        value="0.11493" />
      <inertia
        ixx="1.7546E-05"
        ixy="5.6286E-21"
        ixz="2.0529E-21"
        iyy="0.0001712"
        iyz="-2.9655E-21"
        izz="0.00017089" />
    </inertial>
    <visual>
      <origin
        xyz="-0.175 -0.055 0.185"
        rpy="0 0 0" />
      <geometry>
        <mesh
          filename="package://bot1/meshes/LA.STL" />
      </geometry>
      <material
        name="">
        <color
          rgba="0.79216 0.81961 0.93333 1" />
      </material>
    </visual>
    <collision>
      <origin
        xyz="-0.175 -0.055 0.185"
        rpy="0 0 0" />
      <geometry>
        <mesh
          filename="package://bot1/meshes/LA.STL" />
      </geometry>
    </collision>
  </link>
  <joint
    name="LAJ"
    type="fixed">
    <origin
      xyz="0.175 0.185 0.055"
      rpy="1.5708 0 0" />
    <parent
      link="base_link" />
    <child
      link="LA" />
    <axis
      xyz="0 0 0" />
    <safety_controller
      k_velocity="0" />
  </joint>
  <link
    name="LF">
    <inertial>
      <origin
        xyz="0.075327 6.9389E-18 0.0052437"
        rpy="0 0 0" />
      <mass
        value="0.24614" />
      <inertia
        ixx="0.00024699"
        ixy="2.2224E-20"
        ixz="-4.7172E-05"
        iyy="0.00069522"
        iyz="-1.3368E-20"
        izz="0.00092098" />
    </inertial>
    <visual>
      <origin
        xyz="0 0 0"
        rpy="0 0 0" />
      <geometry>
        <mesh
          filename="package://bot1/meshes/LF.STL" />
      </geometry>
      <material
        name="">
        <color
          rgba="0.79216 0.81961 0.93333 1" />
      </material>
    </visual>
    <collision>
      <origin
        xyz="0 0 0"
        rpy="0 0 0" />
      <geometry>
        <mesh
          filename="package://bot1/meshes/LF.STL" />
      </geometry>
    </collision>
  </link>
  <joint
    name="LFJ"
    type="revolute">
    <origin
      xyz="0.135 0 0"
      rpy="0 -0.64739 0" />
    <parent
      link="LA" />
    <child
      link="LF" />
    <axis
      xyz="0 1 0" />
    <limit
      lower="-1.309"
      upper="0.7854"
      effort="100"
      velocity="0.125" />
    <safety_controller
      k_velocity="0" />
  </joint>
  <link
    name="F">
    <inertial>
      <origin
        xyz="0 0 0"
        rpy="0 0 0" />
      <mass
        value="0" />
      <inertia
        ixx="0"
        ixy="0"
        ixz="0"
        iyy="0"
        iyz="0"
        izz="0" />
    </inertial>
    <visual>
      <origin
        xyz="-0.165 0 0"
        rpy="0 0 0" />
      <geometry>
        <mesh
          filename="package://bot1/meshes/F.STL" />
      </geometry>
      <material
        name="">
        <color
          rgba="1 1 1 1" />
      </material>
    </visual>
    <collision>
      <origin
        xyz="0 0 0"
        rpy="0 0 0" />
      <geometry>
        <mesh
          filename="package://bot1/meshes/F.STL" />
      </geometry>
    </collision>
  </link>
  <joint
    name="FJ"
    type="prismatic">
    <origin
      xyz="0.165 0 0.001"
      rpy="1.5708 0 0" />
    <parent
      link="base_link" />
    <child
      link="F" />
    <axis
      xyz="0 -1 0" />
    <limit
      lower="-0.18"
      upper="0"
      effort="100"
      velocity="0.1" />
    <safety_controller
      k_velocity="0" />
  </joint>
  <link
    name="FC">
    <inertial>
      <origin
        xyz="0.015 0 1.3105E-16"
        rpy="0 0 0" />
      <mass
        value="0.075" />
      <inertia
        ixx="3.125E-05"
        ixy="5.4323E-22"
        ixz="-2.4651E-36"
        iyy="2.125E-05"
        iyz="-1.8149E-21"
        izz="2.125E-05" />
    </inertial>
    <visual>
      <origin
        xyz="0 0 0"
        rpy="0 0 0" />
      <geometry>
        <mesh
          filename="package://bot1/meshes/FC.STL" />
      </geometry>
      <material
        name="">
        <color
          rgba="0.79216 0.81961 0.93333 1" />
      </material>
    </visual>
    <collision>
      <origin
        xyz="0 0 0"
        rpy="0 0 0" />
      <geometry>
        <mesh
          filename="package://bot1/meshes/FC.STL" />
      </geometry>
    </collision>
  </link>
  <joint
    name="FCJ"
    type="fixed">
    <origin
      xyz="0.01 0.275 0"
      rpy="0 0 0" />
    <parent
      link="F" />
    <child
      link="FC" />
    <axis
      xyz="0 0 0" />
    <safety_controller
      k_velocity="0" />
  </joint>
  <link
    name="L">
    <inertial>
      <origin
        xyz="0.025 1.3878E-17 1.1371E-16"
        rpy="0 0 0" />
      <mass
        value="0.075" />
      <inertia
        ixx="3.125E-05"
        ixy="2.5429E-36"
        ixz="-5.8031E-37"
        iyy="2.125E-05"
        iyz="-2.9499E-21"
        izz="2.125E-05" />
    </inertial>
    <visual>
      <origin
        xyz="0 0 0"
        rpy="0 0 0" />
      <geometry>
        <mesh
          filename="package://bot1/meshes/L.STL" />
      </geometry>
      <material
        name="">
        <color
          rgba="0.79216 0.81961 0.93333 1" />
      </material>
    </visual>
    <collision>
      <origin
        xyz="0 0 0"
        rpy="0 0 0" />
      <geometry>
        <mesh
          filename="package://bot1/meshes/L.STL" />
      </geometry>
    </collision>
  </link>
  <joint
    name="LJ"
    type="fixed">
    <origin
      xyz="0 0.05 0"
      rpy="0 0 0" />
    <parent
      link="F" />
    <child
      link="L" />
    <axis
      xyz="0 0 0" />
    <safety_controller
      k_velocity="0" />
  </joint>
</robot>
