<?xml version="1.0" encoding="utf-8"?>

<robot
  name="bot1">

  <material name="black">
    <color rgba="0.0 0.0 0.0 1.0"/>
  </material>

  <material name="blue">
    <color rgba="0.0 0.0 0.8 1.0"/>
  </material>

  <material name="green">
    <color rgba="0.0 0.8 0.0 1.0"/>
  </material>

  <material name="grey">
    <color rgba="0.3 0.3 0.3 1.0"/>
  </material>

  <material name="orange">
    <color rgba="1 0.4 0.1 1"/>
  </material>

  <material name="red">
    <color rgba="0.8 0.0 0.0 1.0"/>
  </material>

  <material name="white">
    <color rgba="1.0 1.0 1.0 1.0"/>
  </material>

  <material name="yellow">
    <color rgba="0.9 0.9 0 1.0"/>
  </material>

  <material name="cyan">
    <color rgba="0.4 0.7 1 1.0"/>
  </material>

  <link
    name="base_link">
    <inertial>
      <origin
        xyz="0.039257 -4.0622E-17 0.070013"
        rpy="0 0 0" />
      <mass
        value="2.519" />
      <inertia
        ixx="0.08053"
        ixy="3.9377E-17"
        ixz="0.00086253"
        iyy="0.039047"
        iyz="4.6655E-18"
        izz="0.097896" />
    </inertial>
    <visual>
      <origin
        xyz="0 0 0"
        rpy="0 0 0" />
      <geometry>
        <mesh
          filename="package://bot4/meshes/base_link.STL" />
      </geometry>
      <material
        name="">
        <color
          rgba="0.79216 0.81961 0.93333 1" />
      </material>
    </visual>
    <collision>
      <origin
        xyz="0 0 0"
        rpy="0 0 0" />
      <geometry>
        <mesh
          filename="package://bot4/meshes/base_link.STL" />
      </geometry>
    </collision>
  </link>
  <link
    name="B">
    <inertial>
      <origin
        xyz="0.005 0.1 2.2811E-17"
        rpy="0 0 0" />
      <mass
        value="0.76" />
      <inertia
        ixx="0.011679"
        ixy="1.0729E-20"
        ixz="1.7754E-20"
        iyy="0.0091517"
        iyz="1.7658E-19"
        izz="0.0025397" />
    </inertial>
    <visual>
      <origin
        xyz="0.175 0 0"
        rpy="0 0 0" />
      <geometry>
        <mesh
          filename="package://bot1/meshes/B.STL" />
      </geometry>
      <material
        name="yellow">
      </material>
    </visual>
    <collision>
      <origin
        xyz="0.175 0 0"
        rpy="0 0 0" />
      <geometry>
        <mesh
          filename="package://bot1/meshes/B.STL" />
      </geometry>
        <surface>
         <bounce>
          <restitution_coefficient>-0.5</restitution_coefficient>
          <threshold>1000</threshold>
         </bounce>
         <contact>
          <ode>
           <max_vel>0</max_vel>
          </ode>
         </contact>
        </surface>
    </collision>
  </link>
  <joint
    name="BJ"
    type="prismatic">
    <origin
      xyz="-0.175 0 0.001"
      rpy="1.5708 0 0" />
    <parent
      link="base_link" />
    <child
      link="B" />
    <axis
      xyz="0 -1 0" />
    <limit
      lower="-0.15"
      upper="0"
      effort="1000"
      velocity="0.1" />
    <!--safety_controller
      k_velocity="0" /-->
  </joint>
  <link
    name="FRW">
    <inertial>
      <origin
        xyz="-0.046186 -0.019179 -0.048696"
        rpy="0 0 0" />
      <mass
        value="0.23606" />
      <inertia
        ixx="0.00022129"
        ixy="2.7105E-20"
        ixz="1.9555E-21"
        iyy="0.00022142"
        iyz="-5.846E-08"
        izz="0.00040743" />
    </inertial>
    <visual>
      <origin
        xyz="0.046186 0.019179 0"
        rpy="0 0 0" />
      <geometry>
        <mesh
          filename="package://bot4/meshes/FRW.STL" />
      </geometry>
      <material
        name="w1c">
        <color
          rgba="0.79216 0.81961 0.93333 1" />
      </material>
    </visual>
    <collision>
      <origin
        xyz="0.046186 0.019179 0"
        rpy="0 0 0" />
      <geometry>
        <mesh
          filename="package://bot4/meshes/FRW.STL" />
      </geometry>
    </collision>
  </link>
  <joint
    name="FRWJ"
    type="continuous">
    <origin
      xyz="0.145 -0.17 0.047"
      rpy="1.5707963267949 0.39309481042652 -3.14159265358979" />
    <parent
      link="base_link" />
    <child
      link="FRW" />
    <axis
      xyz="0 0 1" />
    <!--safety_controller
      k_velocity="0" /-->
  </joint>
  <link
    name="RRW">
    <inertial>
      <origin
        xyz="0.078517 0.032533 -0.048696"
        rpy="0 0 0" />
      <mass
        value="0.23606" />
      <inertia
        ixx="0.00022129"
        ixy="3.3881E-20"
        ixz="1.1117E-21"
        iyy="0.00022142"
        iyz="-5.846E-08"
        izz="0.00040743" />
    </inertial>
    <visual>
      <origin
        xyz="-0.078517 -0.032533 0"
        rpy="0 0 0" />
      <geometry>
        <mesh
          filename="package://bot4/meshes/RRW.STL" />
      </geometry>
      <material
        name="w2c">
        <color
          rgba="0.79216 0.81961 0.93333 1" />
      </material>
    </visual>
    <collision>
      <origin
        xyz="-0.078517 -0.032533 0"
        rpy="0 0 0" />
      <geometry>
        <mesh
          filename="package://bot4/meshes/RRW.STL" />
      </geometry>
    </collision>
  </link>
  <joint
    name="RRWJ"
    type="continuous">
    <origin
      xyz="-0.150 -0.17 0.047"
      rpy="1.5707963267949 0.393094810426521 -3.14159265358979" />
    <parent
      link="base_link" />
    <child
      link="RRW" />
    <axis
      xyz="0 0 1" />
    <!--safety_controller
      k_velocity="0" /-->
  </joint>
  <link
    name="FLW">
    <inertial>
      <origin
        xyz="0.05 -2.6617E-05 -0.048696"
        rpy="0 0 0" />
      <mass
        value="0.23606" />
      <inertia
        ixx="0.00022129"
        ixy="-2.1925E-22"
        ixz="1.5305E-20"
        iyy="0.00022142"
        iyz="-5.846E-08"
        izz="0.00040743" />
    </inertial>
    <visual>
      <origin
        xyz="-0.050 0 0"
        rpy="0 0 0" />
      <geometry>
        <mesh
          filename="package://bot4/meshes/FLW.STL" />
      </geometry>
      <material
        name="">
        <color
          rgba="0.79216 0.81961 0.93333 1" />
      </material>
    </visual>
    <collision>
      <origin
        xyz="-0.050 0 0"
        rpy="0 0 0" />
      <geometry>
        <mesh
          filename="package://bot4/meshes/FLW.STL" />
      </geometry>
    </collision>
  </link>
  <joint
    name="FLWJ"
    type="continuous">
    <origin
      xyz="0.145 0.17 0.047"
      rpy="1.5707963267949 0 0" />
    <parent
      link="base_link" />
    <child
      link="FLW" />
    <axis
      xyz="0 0 -1" />
    <!--safety_controller
      k_velocity="0" /-->
  </joint>
  <link
    name="RLW">
    <inertial>
      <origin
        xyz="-0.085 -2.6617E-05 -0.048696"
        rpy="0 0 0" />
      <mass
        value="0.23606" />
      <inertia
        ixx="0.00022129"
        ixy="-2.1925E-22"
        ixz="1.5305E-20"
        iyy="0.00022142"
        iyz="-5.846E-08"
        izz="0.00040743" />
    </inertial>
    <visual>
      <origin
        xyz="0.085 0 0"
        rpy="0 0 0" />
      <geometry>
        <mesh
          filename="package://bot4/meshes/RLW.STL" />
      </geometry>
      <material
        name="">
        <color
          rgba="0.79216 0.81961 0.93333 1" />
      </material>
    </visual>
    <collision>
      <origin
        xyz="0.085 0 0"
        rpy="0 0 0" />
      <geometry>
        <mesh
          filename="package://bot4/meshes/RLW.STL" />
      </geometry>
    </collision>
  </link>
  <joint
    name="RLWJ"
    type="continuous">
    <origin
      xyz="-0.150 0.17 0.047"
      rpy="1.5707963267949 0 0" />
    <parent
      link="base_link" />
    <child
      link="RLW" />
    <axis
      xyz="0 0 -1" />
    <!--safety_controller
      k_velocity="0" /-->
  </joint>

### <!--removed cameras--> ###

  <!--link
    name="RC">
    <inertial>
      <origin
        xyz="0.015 0 0"
        rpy="0 0 0" />
      <mass
        value="0.075" />
      <inertia
        ixx="3.125E-05"
        ixy="-1.6263E-22"
        ixz="4.2352E-22"
        iyy="2.125E-05"
        iyz="-1.0334E-21"
        izz="2.125E-05" />
    </inertial>
    <visual>
      <origin
        xyz="0 0 0"
        rpy="0 0 0" />
      <geometry>
        <mesh
          filename="package://bot1/meshes/RC.STL" />
      </geometry>
      <material
        name="blue">
      </material>
    </visual>
    <collision>
      <origin
        xyz="0 0 0"
        rpy="0 0 0" />
      <geometry>
        <mesh
          filename="package://bot1/meshes/RC.STL" />
      </geometry>
    </collision>
  </link>
  <joint
    name="RCJ"
    type="fixed">
    <origin
      xyz="0.03 -0.23 0.125"
      rpy="1.5707963267949 1.57 3.14" />
    <parent
      link="base_link" />
    <child
      link="RC" />
    <axis
      xyz="0 0 0" />
    <safety_controller
      k_velocity="0" />
  </joint-->
  <!--link
    name="LC">
    <inertial>
      <origin
        xyz="0.015 0 0"
        rpy="0 0 0" />
      <mass
        value="0.075" />
      <inertia
        ixx="3.125E-05"
        ixy="1.6263E-22"
        ixz="-4.2352E-22"
        iyy="2.125E-05"
        iyz="-1.0334E-21"
        izz="2.125E-05" />
    </inertial>
    <visual>
      <origin
        xyz="0 0 0"
        rpy="0 0 0" />
      <geometry>
        <mesh
          filename="package://bot1/meshes/LC.STL" />
      </geometry>
      <material
        name="blue">
      </material>
    </visual>
    <collision>
      <origin
        xyz="0 0 0"
        rpy="0 0 0" />
      <geometry>
        <mesh
          filename="package://bot1/meshes/LC.STL" />
      </geometry>
    </collision>
  </link>
  <joint
    name="LCJ"
    type="fixed">
    <origin
      xyz="0.03 0.20 0.125"
      rpy="0 0 -4.71" />
    <parent
      link="base_link" />
    <child
      link="LC" />
    <axis
      xyz="0 0 0" />
    <safety_controller
      k_velocity="0" />
  </joint-->
  <link
    name="RA">
    <inertial>
      <origin
        xyz="0.03947 0 0"
        rpy="0 0 0" />
      <mass
        value="0.069926" />
      <inertia
        ixx="1.0796E-05"
        ixy="-1.2701E-21"
        ixz="-4.0392E-21"
        iyy="4.4646E-05"
        iyz="-1.5262E-21"
        izz="4.4339E-05" />
    </inertial>
    <visual>
      <origin
        xyz="0 0 0"
        rpy="0 0 0" />
      <geometry>
        <mesh
          filename="package://bot4/meshes/RA.STL" />
      </geometry>
      <material
        name="">
        <color
          rgba="0.79216 0.81961 0.93333 1" />
      </material>
    </visual>
    <collision>
      <origin
        xyz="0 0 0"
        rpy="0 0 0" />
      <geometry>
        <mesh
          filename="package://bot4/meshes/RA.STL" />
      </geometry>
    </collision>
  </link>
  <joint
    name="RAJ"
    type="fixed">
    <origin
      xyz="0.175 -0.185 0.055"
      rpy="1.5707963267949 0 0" />
    <parent
      link="base_link" />
    <child
      link="RA" />
    <axis
      xyz="0 0 0" />
    <safety_controller
      k_velocity="0" />
  </joint>
  <link
    name="RF">
    <inertial>
      <origin
        xyz="0.039971 1.3878E-17 -0.030112"
        rpy="0 0 0" />
      <mass
        value="0.24614" />
      <inertia
        ixx="0.00024699"
        ixy="1.3E-20"
        ixz="-4.7172E-05"
        iyy="0.00069522"
        iyz="1.2931E-20"
        izz="0.00092098" />
    </inertial>
    <visual>
      <origin
        xyz="0.035 0 0.035"
        rpy="0 0 0" />
      <geometry>
        <mesh
          filename="package://bot4/meshes/RF.STL" />
      </geometry>
      <material
        name="">
        <color
          rgba="0.79216 0.81961 0.93333 1" />
      </material>
    </visual>
    <collision>
      <origin
        xyz="0.035 0 0.035"
        rpy="0 0 0" />
      <geometry>
        <mesh
          filename="package://bot4/meshes/RF.STL" />
      </geometry>
    </collision>
  </link>
  <joint
    name="RFJ"
    type="revolute">
    <origin
      xyz="0.085 0 0"
      rpy="0 0.78539816339745 0" />
    <parent
      link="RA" />
    <child
      link="RF" />
    <axis
      xyz="0 1 0" />
    <limit
      lower="-0.8"
      upper="0.9"
      effort="100"
      velocity="0.125" />
    <!--safety_controller
      k_velocity="0" /-->
  </joint>
  <link
    name="LA">
    <inertial>
      <origin
        xyz="0.03947 0 0"
        rpy="0 0 0" />
      <mass
        value="0.069926" />
      <inertia
        ixx="1.0796E-05"
        ixy="-1.0771E-21"
        ixz="1.664E-22"
        iyy="4.4646E-05"
        iyz="-1.5262E-21"
        izz="4.4339E-05" />
    </inertial>
    <visual>
      <origin
        xyz="0 0 0"
        rpy="0 0 0" />
      <geometry>
        <mesh
          filename="package://bot4/meshes/LA.STL" />
      </geometry>
      <material
        name="">
        <color
          rgba="0.79216 0.81961 0.93333 1" />
      </material>
    </visual>
    <collision>
      <origin
        xyz="0 0 0"
        rpy="0 0 0" />
      <geometry>
        <mesh
          filename="package://bot4/meshes/LA.STL" />
      </geometry>
    </collision>
  </link>
  <joint
    name="LAJ"
    type="fixed">
    <origin
      xyz="0.175 0.185 0.055"
      rpy="1.5707963267949 0 0" />
    <parent
      link="base_link" />
    <child
      link="LA" />
    <axis
      xyz="0 0 0" />
    <safety_controller
      k_velocity="0" />
  </joint>
  <link
    name="LF">
    <inertial>
      <origin
        xyz="0.035444 6.9389E-18 0.035399"
        rpy="0 0 0" />
      <mass
        value="0.24614" />
      <inertia
        ixx="0.00024699"
        ixy="2.2315E-20"
        ixz="-4.7172E-05"
        iyy="0.00069522"
        iyz="-1.2708E-20"
        izz="0.00092098" />
    </inertial>
    <visual>
      <origin
        xyz="0.04 0 -0.03"
        rpy="0 0 0" />
      <geometry>
        <mesh
          filename="package://bot4/meshes/LF.STL" />
      </geometry>
      <material
        name="">
        <color
          rgba="0.79216 0.81961 0.93333 1" />
      </material>
    </visual>
    <collision>
      <origin
        xyz="0.04 0 -0.03"
        rpy="0 0 0" />
      <geometry>
        <mesh
          filename="package://bot4/meshes/LF.STL" />
      </geometry>
    </collision>
  </link>
  <joint
    name="LFJ"
    type="revolute">
    <origin
      xyz="0.085 0 0"
      rpy="0 -0.64739213973993 0" />
    <parent
      link="LA" />
    <child
      link="LF" />
    <axis
      xyz="0 1 0" />
    <limit
      lower="-0.9"
      upper="0.8"
      effort="100"
      velocity="0.125" />
    <!--safety_controller
      k_velocity="0" /-->
  </joint>
  <link
    name="F">
    <inertial>
      <origin
        xyz="0 0 0"
        rpy="0 0 0" />
      <mass
        value="0" />
      <inertia
        ixx="0"
        ixy="0"
        ixz="0"
        iyy="0"
        iyz="0"
        izz="0" />
    </inertial>
    <visual>
      <origin
        xyz="-0.165 0 0"
        rpy="0 0 0" />
      <geometry>
        <mesh
          filename="package://bot1/meshes/F.STL" />
      </geometry>
      <material
        name="yellow">
      </material>
    </visual>
    <collision>
      <origin
        xyz="0 0 0"
        rpy="0 0 0" />
      <geometry>
        <mesh
          filename="package://bot1/meshes/F.STL" />
      </geometry>
    </collision>
  </link>
  <joint
    name="FJ"
    type="prismatic">
    <origin
      xyz="0.165 0 0.001"
      rpy="1.5708 0 0" />
    <parent
      link="base_link" />
    <child
      link="F" />
    <axis
      xyz="0 -1 0" />
    <limit
      lower="-0.18"
      upper="0"
      effort="10"
      velocity="0.05" />
    <!--safety_controller
      k_velocity="0" /-->
  </joint>
  <link
    name="FC">
    <inertial>
      <origin
        xyz="0.015 0 1.3105E-16"
        rpy="0 0 0" />
      <mass
        value="0.075" />
      <inertia
        ixx="3.125E-05"
        ixy="5.4323E-22"
        ixz="-2.4651E-36"
        iyy="2.125E-05"
        iyz="-1.8149E-21"
        izz="2.125E-05" />
    </inertial>
    <visual>
      <origin
        xyz="0 0 0"
        rpy="0 0 0" />
      <geometry>
        <mesh
          filename="package://bot1/meshes/FC.STL" />
      </geometry>
      <material
        name="blue">
      </material>
    </visual>
    <collision>
      <origin
        xyz="0 0 0"
        rpy="0 0 0" />
      <geometry>
        <mesh
          filename="package://bot1/meshes/FC.STL" />
      </geometry>
    </collision>
  </link>
  <joint
    name="FCJ"
    type="fixed">
    <origin
      xyz="0.01 0.275 0"
      rpy="-1.57 0 0" />
    <parent
      link="F" />
    <child
      link="FC" />
    <axis
      xyz="0 0 0" />
    <!--safety_controller
      k_velocity="0" /-->
  </joint>
  <link
    name="L">
    <inertial>
      <origin
        xyz="0.025 1.3878E-17 1.1371E-16"
        rpy="0 0 0" />
      <mass
        value="0.075" />
      <inertia
        ixx="3.125E-05"
        ixy="2.5429E-36"
        ixz="-5.8031E-37"
        iyy="2.125E-05"
        iyz="-2.9499E-21"
        izz="2.125E-05" />
    </inertial>
    <visual>
      <origin
        xyz="0 0 0"
        rpy="0 0 0" />
      <geometry>
        <mesh
          filename="package://bot1/meshes/L.STL" />
      </geometry>
      <material
        name="green">
      </material>
    </visual>
    <collision>
      <origin
        xyz="0 0 0"
        rpy="0 0 0" />
      <geometry>
        <mesh
          filename="package://bot1/meshes/L.STL" />
      </geometry>
    </collision>
  </link>
  <joint
    name="LJ"
    type="fixed">
    <origin
      xyz="0 0.05 0"
      rpy="0 0 0" />
    <parent
      link="F" />
    <child
      link="L" />
    <axis
      xyz="0 0 0" />
    <!--safety_controller
      k_velocity="0" /-->
  </joint>
  
  <!--LiDAR-->
  <link name="hokuyo_link">
    <collision>
      <origin xyz="0 0 0" rpy="0 0 0"/>
      <geometry>
    <box size="0.1 0.1 0.1"/>
      </geometry>
    </collision>

    <visual>
      <origin xyz="0 0 0" rpy="0 0 0"/>
      <geometry>
        <mesh filename="package://bot1/meshes/hokuyo.dae"/>
      </geometry>
    </visual>

    <inertial>
      <mass value="1e-5" />
      <origin xyz="0 0 0" rpy="0 0 0"/>
      <inertia ixx="1e-6" ixy="0" ixz="0" iyy="1e-6" iyz="0" izz="1e-6" />
    </inertial>
  </link>

  <joint name="hokuyo_joint" type="fixed">
    <origin
      xyz="0.04 0.04 0"
      rpy="-1.57 0 0" />
    <parent
      link="F" />
	<child link="hokuyo_link"/>
    <axis
      xyz="0 1 0" />
    <!-- <safety_controller
      k_velocity="0" /> -->
  </joint>

   <gazebo reference="hokuyo_link">
    <sensor type="ray" name="head_hokuyo_sensor">
      <pose>0 0 0 0 0 0</pose>
      <visualize>true</visualize>
      <update_rate>40</update_rate>
      <ray>
        <scan>
          <horizontal>
            <samples>21</samples>
            <resolution>1</resolution>
            <min_angle>-0.000001</min_angle>
            <max_angle>0.000001</max_angle>
          </horizontal>
        </scan>
        <range>
          <min>0.20</min>
          <max>3.0</max>
          <resolution>0.01</resolution>
        </range>
        <noise>
          <type>gaussian</type>
          <!-- Noise parameters based on published spec for Hokuyo laser
               achieving "+-30mm" accuracy at range < 10m.  A mean of 0.0m and
               stddev of 0.01m will put 99.7% of samples within 0.03m of the true
               reading. -->
          <mean>0.0</mean>
          <stddev>0.01</stddev>
        </noise>
      </ray>
      <plugin name="gazebo_ros_head_hokuyo_controller" filename="libgazebo_ros_laser.so">
        <topicName>/umic_bot/laser/scan</topicName>
        <frameName>hokuyo_link</frameName>
      </plugin>
    </sensor>
  </gazebo>

	<!--SONAR-->
 <joint name="sonar_front_joint" type="fixed">
    <origin
      xyz="0.09 0.015 -0.02"
      rpy="3.1415926 0 -1.570796326" />
    <parent
      link="LA" />
	<child link="sonar_link"/>
    <axis
      xyz="0 1 0" />
</joint>
<link name="sonar_link">
    <collision>
      <origin xyz="0 0 0" rpy="0 0 0"/>
      <geometry>
        <box size="0.01 0.01 0.01"/>
      </geometry>
    </collision>
    <visual>
      <origin xyz="0 0 0" rpy="0 0 0"/>
      <geometry>
        <box size="0.01 0.01 0.01"/>
      </geometry>
    </visual>
    <inertial>
      <mass value="1e-5" />
      <origin xyz="0 0 0" rpy="0 0 0"/>
      <inertia ixx="1e-6" ixy="0" ixz="0" iyy="1e-6" iyz="0" izz="1e-6" />
    </inertial>
 </link>
 
 <!--SONAR PLUGIN-->
 
 <gazebo reference="sonar_link">        
   <sensor type="ray" name="TeraRanger">
      <pose>0 0 0 0 0 0</pose>
      <visualize>true</visualize>
      <update_rate>50</update_rate>
      <ray>
         <scan>
            <horizontal>
               <samples>10</samples>
               <resolution>1</resolution> 
               <min_angle>-0.51</min_angle>
               <max_angle>-0.68</max_angle>
            </horizontal>
            <!-- <vertical>
               <samples>10</samples>
               <resolution>1</resolution> 
               <min_angle>-0.14835</min_angle>
               <max_angle>0.14835</max_angle> 
            </vertical> -->
         </scan>
         <range>
            <min>0.01</min>
            <max>2</max>
            <resolution>0.001</resolution>
         </range>
      </ray>
      <plugin filename="libgazebo_ros_range.so" name="gazebo_ros_range">
         <gaussianNoise>0.001</gaussianNoise>
         <alwaysOn>true</alwaysOn>
         <updateRate>50</updateRate>
         <topicName>sensor/sonar_front</topicName>
         <frameName>base_ir_front</frameName>
         <radiation>INFRARED</radiation>
         <fov>0.2967</fov>
      </plugin>
   </sensor>  
   </gazebo>

  <!--mimic plugin-->
   <mimic_joint_plugin_gazebo
      name_prefix="LFJ"
      parent_joint="RFJ" mimic_joint="LFJ"
      multiplier="-1.0"
      max_effort="100.0" />
   <gazebo>
    <plugin name="mimic_joint_plugin" filename="libroboticsgroup_gazebo_mimic_joint_plugin.so">
     <joint>RFJ</joint>
     <mimicJoint>LFJ</mimicJoint>
     <multiplier>-1</multiplier>
     <offset>0</offset>
     <maxEffort>100.0</maxEffort>
    </plugin>
   </gazebo> 
	
	<!--camera plugins-->
  <gazebo reference="FC">
    <material>Gazebo/Green</material>
    <sensor type="camera" name="cameraFC">
      <update_rate>30.0</update_rate>
      <camera name="front_cam">
        <horizontal_fov>1.3962634</horizontal_fov>
        <image>
          <width>800</width>
          <height>800</height>
          <format>R8G8B8</format>
        </image>
        <clip>
          <near>0.02</near>
          <far>300</far>
        </clip>
      </camera>
      <plugin name="camera_controller" filename="libgazebo_ros_camera.so">
        <alwaysOn>true</alwaysOn>
        <updateRate>0.0</updateRate>
        <cameraName>mybot/camera1</cameraName>
        <imageTopicName>image_raw</imageTopicName>
        <cameraInfoTopicName>camera_info</cameraInfoTopicName>
        <frameName>camera</frameName>
        <hackBaseline>0.07</hackBaseline>
        <distortionK1>0.0</distortionK1>
        <distortionK2>0.0</distortionK2>
        <distortionK3>0.0</distortionK3>
        <distortionT1>0.0</distortionT1>
        <distortionT2>0.0</distortionT2>
      </plugin>
    </sensor>
  </gazebo>
   

  <!--Physical parameters-->
    <gazebo reference="FLW">
      <mu1 value="10000000.0"/>
      <mu2 value="10000000.0"/>
      <kp value="10000000.0" />
      <kd value="1.0" />
    </gazebo>  

    <gazebo reference="FLW">
      <mu1 value="1000000.0"/>
      <mu2 value="1000000.0"/>
      <kp value="10000000.0" />
      <kd value="1.0" />
    </gazebo>  

    <gazebo reference="FLW">
      <mu1 value="1000000.0"/>
      <mu2 value="1000000.0"/>
      <kp value="10000000.0" />
      <kd value="1.0" />
    </gazebo>  

    <gazebo reference="FLW">
      <mu1 value="1000000.0"/>
      <mu2 value="1000000.0"/>
      <kp value="10000000.0" />
      <kd value="1.0" />
    </gazebo>  

  <!--Differential_Transmissions-->
    <transmission name="FLW_trans">
      <type>transmission_interface/SimpleTransmission</type>
      <actuator name="FLW_wheel_motor">
        <mechanicalReduction>1</mechanicalReduction>
      </actuator>
      <joint name="FLWJ">
        <hardwareInterface>VelocityJointInterface</hardwareInterface>
      </joint>
    </transmission>

    <transmission name="FRW_trans">
      <type>transmission_interface/SimpleTransmission</type>
      <actuator name="FRW_wheel_motor">
        <mechanicalReduction>1</mechanicalReduction>
      </actuator>
      <joint name="FRWJ">
        <hardwareInterface>VelocityJointInterface</hardwareInterface>
      </joint>
    </transmission>

    <transmission name="RLW_trans">
      <type>transmission_interface/SimpleTransmission</type>
      <actuator name="RLW_wheel_motor">
        <mechanicalReduction>1</mechanicalReduction>
      </actuator>
      <joint name="RLWJ">
        <hardwareInterface>VelocityJointInterface</hardwareInterface>
      </joint>
    </transmission>

    <transmission name="RRW_trans">
      <type>transmission_interface/SimpleTransmission</type>
      <actuator name="RRW_wheel_motor">
        <mechanicalReduction>1</mechanicalReduction>
      </actuator>
      <joint name="RRWJ">
        <hardwareInterface>VelocityJointInterface</hardwareInterface>
      </joint>
    </transmission>

  <!--Gates_Transmission-->
    <transmission name="Front_Gate_Trans" type="SimpleTransmission">
      <type>transmission_interface/SimpleTransmission</type>
      <actuator name="Front_Gate_motor">
        <mechanicalReduction>1</mechanicalReduction>
      </actuator>
      <joint name="FJ">
        <hardwareInterface>EffortJointInterface</hardwareInterface>
      </joint>
    </transmission>

    <transmission name="Back_Gate_Trans" type="SimpleTransmission">
      <type>transmission_interface/SimpleTransmission</type>
      <actuator name="Back_Gate_Motor">
        <mechanicalReduction>1</mechanicalReduction>
      </actuator>
      <joint name="BJ">
        <hardwareInterface>EffortJointInterface</hardwareInterface>
      </joint>
    </transmission>

  <!--Flaps Transmission-->
    <transmission name="left_flap_Trans" type="SimpleTransmission">
      <type>transmission_interface/SimpleTransmission</type>
      <actuator name="left_flap_motor">
        <mechanicalReduction>1</mechanicalReduction>
      </actuator>
      <joint name="LFJ">
        <hardwareInterface>EffortJointInterface</hardwareInterface>
      </joint>
    </transmission>

    <transmission name="right_flap_Trans" type="SimpleTransmission">
      <type>transmission_interface/SimpleTransmission</type>
      <actuator name="right_flap_motor">
        <mechanicalReduction>1</mechanicalReduction>
      </actuator>
      <joint name="RFJ">
        <hardwareInterface>EffortJointInterface</hardwareInterface>
      </joint>
    </transmission>
   
  <!-- Gazebo plugin for ROS Control -->
   <gazebo>
     <plugin name="gazebo_ros_control" filename="libgazebo_ros_control.so">
     </plugin>
   </gazebo>

   <gazebo reference="base_link">
   <visual>
     <material>
       <ambient>${170.0/255.0} ${5.0/255.0} ${5.0/255.0} 1.0</ambient>
       <diffuse>${170.0/255.0} ${5.0/255.0} ${5.0/255.0} 1.0</diffuse>
       <specular>${170.0/255.0} ${5.0/255.0} ${5.0/255.0} 1.0</specular>
       <emissive>0.0 0.0 0.0 0.0</emissive>
     </material>
   </visual>
 </gazebo>

 <gazebo reference="B">
  <visual>
    <material>
      <ambient>${185.0/255.0} ${125.0/255.0} ${16.0/255.0} 1.0</ambient>
      <diffuse>${185.0/255.0} ${125.0/255.0} ${16.0/255.0} 1.0</diffuse>
      <specular>${185.0/255.0} ${125.0/255.0} ${16.0/255.0} 1.0</specular>
      <emissive>0.0 0.0 0.0 0.0</emissive>
    </material>
  </visual>
</gazebo>

<gazebo reference="F">
  <visual>
    <material>
      <ambient>${185.0/255.0} ${125.0/255.0} ${16.0/255.0} 1.0</ambient>
      <diffuse>${185.0/255.0} ${125.0/255.0} ${16.0/255.0} 1.0</diffuse>
      <specular>${185.0/255.0} ${125.0/255.0} ${16.0/255.0} 1.0</specular>
      <emissive>0.0 0.0 0.0 0.0</emissive>
    </material>
  </visual>
</gazebo>

<gazebo reference="LF">
  <visual>
    <material>
      <ambient>${103.0/255.0} ${199.0/255.0} ${235.0/255.0} 1.0</ambient>
      <diffuse>${103.0/255.0} ${199.0/255.0} ${235.0/255.0} 1.0</diffuse>
      <specular>${103.0/255.0} ${199.0/255.0} ${235.0/255.0} 1.0</specular>
      <emissive>0.0 0.0 0.0 0.0</emissive>
    </material>
  </visual>
</gazebo>

<gazebo reference="RF">
  <visual>
    <material>
      <ambient>${103.0/255.0} ${199.0/255.0} ${235.0/255.0} 1.0</ambient>
      <diffuse>${103.0/255.0} ${199.0/255.0} ${235.0/255.0} 1.0</diffuse>
      <specular>${103.0/255.0} ${199.0/255.0} ${235.0/255.0} 1.0</specular>
      <emissive>0.0 0.0 0.0 0.0</emissive>
    </material>
  </visual>
</gazebo>

<gazebo reference="FLW">
  <visual>
    <material>
      <ambient>0 0 0 1.0</ambient>
      <diffuse>0 0 0 1.0</diffuse>
      <specular>0 0 0 1.0</specular>
      <emissive>0.0 0.0 0.0 0.0</emissive>
    </material>
  </visual>
</gazebo>

<gazebo reference="FRW">
  <visual>
    <material>
      <ambient>0 0 0 1.0</ambient>
      <diffuse>0 0 0 1.0</diffuse>
      <specular>0 0 0 1.0</specular>
      <emissive>0.0 0.0 0.0 0.0</emissive>
    </material>
  </visual>
</gazebo>

<gazebo reference="RLW">
  <visual>
    <material>
      <ambient>0 0 0 1.0</ambient>
      <diffuse>0 0 0 1.0</diffuse>
      <specular>0 0 0 1.0</specular>
      <emissive>0.0 0.0 0.0 0.0</emissive>
    </material>
  </visual>
</gazebo>

<gazebo reference="RRW">
  <visual>
    <material>
      <ambient>0 0 0 1.0</ambient>
      <diffuse>0 0 0 1.0</diffuse>
      <specular>0 0 0 1.0</specular>
      <emissive>0.0 0.0 0.0 0.0</emissive>
    </material>
  </visual>
</gazebo>

<gazebo reference="RRW">
  <visual>
    <material>
      <ambient>0 0 0 1.0</ambient>
      <diffuse>0 0 0 1.0</diffuse>
      <specular>0 0 0 1.0</specular>
      <emissive>0.0 0.0 0.0 0.0</emissive>
    </material>
  </visual>
</gazebo>

</robot>
